Failure # 1 (occurred at 2023-01-05_01-47-48)
Traceback (most recent call last):
  File "C:\Users\Xander\AppData\Roaming\Python\Python38\site-packages\ray\tune\execution\ray_trial_executor.py", line 1050, in get_next_executor_event
    future_result = ray.get(ready_future)
  File "C:\Users\Xander\AppData\Roaming\Python\Python38\site-packages\ray\_private\client_mode_hook.py", line 105, in wrapper
    return func(*args, **kwargs)
  File "C:\Users\Xander\AppData\Roaming\Python\Python38\site-packages\ray\_private\worker.py", line 2291, in get
    raise value
  File "python\ray\_raylet.pyx", line 1032, in ray._raylet.task_execution_handler
  File "python\ray\_raylet.pyx", line 812, in ray._raylet.execute_task
  File "python\ray\_raylet.pyx", line 980, in ray._raylet.execute_task
  File "python\ray\_raylet.pyx", line 593, in ray._raylet.store_task_errors
ray.exceptions.RayActorError: The actor died because of an error raised in its creation task, [36mray::PPO.__init__()[39m (pid=31864, ip=127.0.0.1, repr=PPO)
  File "python\ray\_raylet.pyx", line 859, in ray._raylet.execute_task
  File "python\ray\_raylet.pyx", line 863, in ray._raylet.execute_task
  File "python\ray\_raylet.pyx", line 810, in ray._raylet.execute_task.function_executor
  File "C:\Users\Xander\AppData\Roaming\Python\Python38\site-packages\ray\_private\function_manager.py", line 674, in actor_method_executor
    return method(__ray_actor, *args, **kwargs)
  File "C:\Users\Xander\AppData\Roaming\Python\Python38\site-packages\ray\util\tracing\tracing_helper.py", line 466, in _resume_span
    return method(self, *_args, **_kwargs)
  File "C:\Users\Xander\AppData\Roaming\Python\Python38\site-packages\ray\rllib\algorithms\algorithm.py", line 414, in __init__
    super().__init__(config=config, logger_creator=logger_creator, **kwargs)
  File "C:\Users\Xander\AppData\Roaming\Python\Python38\site-packages\ray\tune\trainable\trainable.py", line 161, in __init__
    self.setup(copy.deepcopy(self.config))
  File "C:\Users\Xander\AppData\Roaming\Python\Python38\site-packages\ray\util\tracing\tracing_helper.py", line 466, in _resume_span
    return method(self, *_args, **_kwargs)
  File "C:\Users\Xander\AppData\Roaming\Python\Python38\site-packages\ray\rllib\algorithms\algorithm.py", line 439, in setup
    self.config = self.merge_trainer_configs(
  File "C:\Users\Xander\AppData\Roaming\Python\Python38\site-packages\ray\rllib\algorithms\algorithm.py", line 2228, in merge_trainer_configs
    return deep_update(
  File "C:\Users\Xander\AppData\Roaming\Python\Python38\site-packages\ray\_private\dict.py", line 60, in deep_update
    raise Exception("Unknown config parameter `{}` ".format(k))
Exception: Unknown config parameter `sdg_minibatch_size`

